2018-03-14 06:29:32 ERROR (MainThread) [homeassistant.core] Error doing job: Task exception was never retrieved
Traceback (most recent call last):
  File "/usr/local/lib/python3.6/asyncio/tasks.py", line 182, in _step
    result = coro.throw(exc)
  File "/usr/local/lib/python3.6/site-packages/homeassistant-0.63.0.dev0-py3.6.egg/homeassistant/components/discovery.py", line 134, in scan_devices
    results = yield from hass.async_add_job(_discover, netdisco)
  File "/usr/local/lib/python3.6/asyncio/futures.py", line 327, in __iter__
    yield self  # This tells Task to wait for completion.
  File "/usr/local/lib/python3.6/asyncio/tasks.py", line 250, in _wakeup
    future.result()
  File "/usr/local/lib/python3.6/asyncio/futures.py", line 243, in result
    raise self._exception
  File "/usr/local/lib/python3.6/concurrent/futures/thread.py", line 56, in run
    result = self.fn(*self.args, **self.kwargs)
  File "/usr/local/lib/python3.6/site-packages/homeassistant-0.63.0.dev0-py3.6.egg/homeassistant/components/discovery.py", line 160, in _discover
    netdisco.scan()
  File "/usr/local/lib/python3.6/site-packages/netdisco/discovery.py", line 54, in scan
    self.mdns.start()
  File "/usr/local/lib/python3.6/site-packages/netdisco/mdns.py", line 21, in start
    self.zeroconf = zeroconf.Zeroconf()
  File "/usr/local/lib/python3.6/site-packages/zeroconf.py", line 1660, in __init__
    self._listen_socket = new_socket()
  File "/usr/local/lib/python3.6/site-packages/zeroconf.py", line 1632, in new_socket
    s.bind(('', _MDNS_PORT))
OSError: [Errno 98] Address already in use
